<?xml version="1.0"?>
<robot xmlns:xacro="http://ros.org/wiki/xacro">

  <xacro:property name="initial_positions_file" default="$(find interbotix_xslocobot_sim)/config/initial_positions.yaml" />
  <xacro:property name="initial_positions" default="${xacro.load_yaml(initial_positions_file)}" />
  <xacro:macro name="pan_and_tilt" params="*origin">

    <joint name="pan" type="revolute">
      <axis xyz="0 0 1" />
      <limit
        effort="2"
        lower="${-pi/2}"
        upper="${pi/2}"
        velocity="${pi}" />
      <xacro:insert_block name="origin" />
      <parent
        link="${robot_name}_camera_tower_link" />
      <child
        link="${robot_name}_pan_link" />
      <dynamics
        friction="0.1"
        damping="0.1" />
    </joint>

    <link name="${robot_name}_pan_link">
      <visual>
        <origin
          rpy="0 0 ${pi/2}"
          xyz="0 0 0" />
        <geometry>
          <mesh
            filename="package://ros2_agents/robots/locobot_wx250s/description/meshes/body/locobot_pan.stl"
            scale="0.001 0.001 0.001" />
        </geometry>
        <material name="interbotix_black" />
      </visual>
      <collision>
        <origin
          rpy="0 0 ${pi/2}"
          xyz="0 0 0" />
        <geometry>
          <mesh
            filename="package://ros2_agents/robots/locobot_wx250s/description/meshes/body/locobot_pan.stl"
            scale="0.001 0.001 0.001" />
        </geometry>
      </collision>
      <inertial>
        <origin
          rpy="0 0 ${pi/2}"
          xyz="0.012 0.000496 0.018504" />
        <mass value="0.098997" />
        <inertia
          ixx="0.0000276300"
          ixy="0.0000000418"
          ixz="0.0000005145"
          iyy="0.0000204300"
          iyz="-0.0000000421"
          izz="0.0000276300" />
      </inertial>
    </link>

    <gazebo reference="${robot_name}_pan_link">
      <material>Gazebo/DarkGrey</material>
      <self_collide>true</self_collide>
    </gazebo>

    <joint name="tilt" type="revolute">
      <axis xyz="0 1 0" />
      <limit
        effort="2"
        lower="${-pi/2}"
        upper="${radians(75)}"
        velocity="${pi}" />
      <origin
        rpy="0 ${initial_positions['tilt']} 0"
        xyz="0.025034 0 0.019" />
      <parent
        link="${robot_name}_pan_link" />
      <child
        link="${robot_name}_tilt_link" />
      <dynamics
        friction="0.1"
        damping="0.1" />
    </joint>

    <link name="${robot_name}_tilt_link">
      <visual>
        <origin
          rpy="0 0 ${pi/2}"
          xyz="0 0 0" />
        <geometry>
          <mesh
            filename="package://ros2_agents/robots/locobot_wx250s/description/meshes/body/locobot_tilt.stl"
            scale="0.001 0.001 0.001" />
        </geometry>
        <material name="interbotix_black" />
      </visual>
      <collision>
        <origin
          rpy="0 0 ${pi/2}"
          xyz="0 0 0" />
        <geometry>
          <mesh
            filename="package://ros2_agents/robots/locobot_wx250s/description/meshes/body/locobot_tilt.stl"
            scale="0.001 0.001 0.001" />
        </geometry>
      </collision>
      <inertial>
        <origin
          rpy="0 0 ${pi/2}"
          xyz="0.0237737000 -0.0000016331 0.0000077432" />
        <mass value="0.019845" />
        <inertia
          ixx="0.0000021677"
          ixy="0.0000000000"
          ixz="0.0000000001"
          iyy="0.0000063634"
          iyz="0.0000000003"
          izz="0.0000066157" />
      </inertial>
    </link>

    <gazebo reference="${robot_name}_tilt_link">
      <material>Gazebo/DarkGrey</material>
      <self_collide>true</self_collide>
    </gazebo>

    <joint name="camera" type="fixed">
      <origin
        rpy="0 0 0"
        xyz="0.05318 0.0175 0.000009" />
      <parent
        link="${robot_name}_tilt_link" />
      <child
        link="camera_${robot_name}_link" />
    </joint>

    <gazebo reference="camera">
      <disableFixedJointLumping>true</disableFixedJointLumping>
    </gazebo>

    <link name="camera_${robot_name}_link">
      <visual>
        <origin
          rpy="0 0 0"
          xyz="0 0 0" />
        <geometry>
          <mesh
            filename="package://ros2_agents/robots/locobot_wx250s/description/meshes/locobot_camera.stl"
            scale="0.001 0.001 0.001" />
        </geometry>
        <material name="">
          <color
            rgba="0.55 0.55 0.55 1" />
        </material>
      </visual>
      <collision>
        <origin
          rpy="0 0 0"
          xyz="0 0 0" />
        <geometry>
          <mesh
            filename="package://ros2_agents/robots/locobot_wx250s/description/meshes/locobot_camera.stl"
            scale="0.001 0.001 0.001" />
        </geometry>
      </collision>
      <inertial>
        <origin
          rpy="0 0 0"
          xyz="-0.008972 -0.015818 0.000003" />
        <mass value="0.072" />
        <inertia
          ixx="0.0000465400"
          ixy="0.0000003028"
          ixz="0.0000000245"
          iyy="0.0000069128"
          iyz="0.0000000248"
          izz="0.0000468600" />
      </inertial>
    </link>

    <gazebo reference="camera_${robot_name}_link">
      <material>Gazebo/Grey</material>
      <self_collide>true</self_collide>
    </gazebo>

    <!-- Adds a dummy link, libgazebo_ros_openni_kinect publishes from frame's z-axis -->
    <!-- https://github.com/ros-simulation/gazebo_ros_pkgs/issues/243 -->
    <joint name="camera_depth_joint" type="fixed">
      <origin rpy="${-pi/2} 0 ${-pi/2}" xyz="0 0 0" />
      <parent link="camera_${robot_name}_link" />
      <child link="${robot_name}_camera_depth_link" />
    </joint>
    <link name="${robot_name}_camera_depth_link">
      <origin rpy="0 0 0" xyz="0 0 0" />
      <!-- <ignition_frame_id>${robot_name}_base_footprint</ignition_frame_id> -->
    </link>
  </xacro:macro>

</robot>