<?xml version="1.0"?>
<robot name="robot_generic">
    <link name="link1">
        <inertial>
            <origin xyz="0 0 0" rpy="0 0 0" />
            <mass value="1.0" />
            <inertia ixx="1.0" ixy="0.0" ixz="0.0"
                iyy="1.0" iyz="0.0" izz="1.0" />
        </inertial>
    </link>
    <link name="link2">
        <inertial>
            <origin xyz="0 0 0" rpy="0 0 0" />
            <mass value="1.0" />
            <inertia ixx="1.0" ixy="0.0" ixz="0.0"
                iyy="1.0" iyz="0.0" izz="1.0" />
        </inertial>
    </link>
    <link name="link3">
        <inertial>
            <origin xyz="0 0 0" rpy="0 0 0" />
            <mass value="1.0" />
            <inertia ixx="1.0" ixy="0.0" ixz="0.0"
                iyy="1.0" iyz="0.0" izz="1.0" />
        </inertial>
    </link>
    <link name="link4">
        <inertial>
            <origin xyz="0 0 0" rpy="0 0 0" />
            <mass value="1.0" />
            <inertia ixx="1.0" ixy="0.0" ixz="0.0"
                iyy="1.0" iyz="0.0" izz="1.0" />
        </inertial>
    </link>
    <joint name="joint1" type="continuous">
        <parent link="link1" />
        <child link="link2" />
        <origin xyz="5 3 0" rpy="0 0 0" />
        <axis xyz="-0.9 0.15 0" />
    </joint>
    <joint name="joint2" type="continuous">
        <parent link="link1" />
        <child link="link3" />
        <origin xyz="-2 5 0" rpy="0 0 1.57" />
        <axis xyz="-0.707 0.707 0" />
    </joint>
    <joint name="joint3" type="continuous">
        <parent link="link3" />
        <child link="link4" />
        <origin xyz="5 0 0" rpy="0 0 -1.57" />
        <axis xyz="0.707 -0.707 0" />
    </joint>
</robot>