<?xml version="1.0"?>
<robot name="mobile_wx250s" xmlns:xacro="http://ros.org/wiki/xacro">

  <xacro:property name="dof"
    value="6"
    scope="global" />

  <xacro:property name="mesh_directory"
    value="package://ros2_transformers/robots/locobot_wx250s/description/meshes/arms" />

  <xacro:property name="pi_offset" value="0.00001" />

  <xacro:property name="initial_positions_file" default="$(find interbotix_xslocobot_sim)/config/initial_positions.yaml" />
  <xacro:property name="initial_positions" default="${xacro.load_yaml(initial_positions_file)}" />
  <xacro:include filename="$(find ros2_transformers)/robots/locobot_wx250s/description/urdf/arms/ar_tag.urdf.xacro" />
  <link name="${robot_name}_arm_base_link">
    <visual>
      <origin
        rpy="${pi/2} 0 ${pi/2}"
        xyz="-0.095773 0 -0.10565023" />
      <geometry>
        <mesh
          filename="${mesh_directory}/base.stl"
          scale="0.001 0.001 0.001" />
      </geometry>
      <material name="interbotix_black" />
    </visual>
    <collision>
      <origin
        rpy="${pi/2} 0 ${pi/2}"
        xyz="-0.095773 0 -0.10565023" />
      <geometry>
        <mesh
          filename="${mesh_directory}/base.stl"
          scale="0.001 0.001 0.001" />
      </geometry>
    </collision>
    <inertial>
      <origin
        rpy="${pi/2} 0 ${pi/2}"
        xyz="-0.0001350000 -0.0000266286 0.0338755000" />
      <mass value="0.379673" />
      <inertia
        ixx="0.0004351000"
        iyy="0.0004452000"
        izz="0.0005731000"
        ixy="0.0000000707"
        ixz="0.0000000266"
        iyz="-0.0000022881" />
    </inertial>
  </link>
<!-- 
    <joint name="arm_base_camera_link" type="fixed">
      <origin rpy="0 0.6 0" xyz="-0.05 0 0.5" />
      <parent link="${robot_name}_arm_base_link" />
      <child link="${robot_name}_arm_base_camera_link" />
    </joint>
    <link name="${robot_name}_arm_base_camera_link">
      <origin rpy="0 0 0" xyz="0 0 0" />
      <ignition_frame_id>/${robot_name}_arm_base_camera_link</ignition_frame_id>
    </link>

  <gazebo reference="${robot_name}_arm_base_camera_link">
    <material>Gazebo/DarkGrey</material>
      <sensor name="camera_arm_base" type="camera">
        <topic>/camera_arm_base</topic>
        <ignition_frame_id>${robot_name}_arm_base_camera_link</ignition_frame_id>
        <always_on>true</always_on>
        <update_rate>5</update_rate>
        <camera name="camera_arm_base">
          <optical_frame_id>${robot_name}_arm_base_camera_link</optical_frame_id>
          <horizontal_fov>0.994837</horizontal_fov>
          <update_rate>10</update_rate>
          <image>
            <format>R8G8B8</format>
            <width>640</width>
            <height>480</height>
          </image>
          <clip>
            <near>0.01</near>
            <far>6</far>
          </clip>

          <distortion>
            <k1>0.00000001</k1>
            <k2>0.00000001</k2>
            <k3>0.00000001</k3>
            <p1>0.00000001</p1>
            <p2>0.00000001</p2>
          </distortion> -->

          <!-- <intrinsics>
            <cx>0</cx>
            <cy>0</cy>
          </intrinsics>
          <projection>
            <fx>0</fx>
            <fy>0</fy>
          </projection> -->
        <!-- </camera>
      </sensor>
      

  </gazebo> -->

  <joint name="waist" type="revolute">
    <axis xyz="0 0 1" />
    <limit
      effort="${waist_limit_effort}"
      lower="${waist_limit_lower}"
      upper="${waist_limit_upper}"
      velocity="${waist_limit_vel}" />
    <origin
      rpy="0 0 ${initial_positions['waist']}"
      xyz="0 -0.08 0.066175" />
    <parent
      link="${robot_name}_arm_base_link" />
    <child
      link="${robot_name}_shoulder_link" />
    <dynamics
      friction="0.1"
      damping="0.1" />
  </joint>

  <link name="${robot_name}_shoulder_link">
    <visual>
      <origin
        rpy="0 0 ${pi/2}"
        xyz="0 0 -0.003" />
      <geometry>
        <mesh
          filename="${mesh_directory}/shoulder.stl"
          scale="0.001 0.001 0.001" />
      </geometry>
      <material name="interbotix_black" />
    </visual>
    <collision>
      <origin
        rpy="0 0 ${pi/2}"
        xyz="0 0 -0.003" />
      <geometry>
        <mesh
          filename="${mesh_directory}/shoulder.stl"
          scale="0.001 0.001 0.001" />
      </geometry>
    </collision>
    <inertial>
      <origin
        rpy="0 0 ${pi/2}"
        xyz="0.0000223482 0.0000414609 0.0066287000" />
      <mass value="0.480879" />
      <inertia
        ixx="0.0003790000"
        iyy="0.0005557000"
        izz="0.0005889000"
        ixy="0.0000000022"
        ixz="-0.0000003561"
        iyz="0.0000012245" />
    </inertial>
  </link>

  <joint name="shoulder" type="revolute">
    <axis xyz="0 1 0" />
    <limit
      effort="${shoulder_limit_effort}"
      lower="${shoulder_limit_lower}"
      upper="${shoulder_limit_upper}"
      velocity="${shoulder_limit_vel}" />
    <origin
      rpy="0 ${initial_positions['shoulder']} 0"
      xyz="0 0 0.03865" />
    <parent
      link="${robot_name}_shoulder_link" />
    <child
      link="${robot_name}_upper_arm_link" />
    <dynamics
      friction="0.1"
      damping="0.1" />
  </joint>

  <link name="${robot_name}_upper_arm_link">
    <visual>
      <origin
        rpy="0 0 ${pi/2}"
        xyz="0 0 0" />
      <geometry>
        <mesh
          filename="${mesh_directory}/upper_arm.stl"
          scale="0.001 0.001 0.001" />
      </geometry>
      <material name="interbotix_black" />
    </visual>
    <collision>
      <origin
        rpy="0 0 ${pi/2}"
        xyz="0 0 0" />
      <geometry>
        <mesh
          filename="${mesh_directory}/upper_arm.stl"
          scale="0.001 0.001 0.001" />
      </geometry>
    </collision>
    <inertial>
      <origin
        rpy="0 0 ${pi/2}"
        xyz="0.0171605000 0.0000002725 0.1913230000" />
      <mass value="0.430811" />
      <inertia
        ixx="0.0034630000"
        iyy="0.0035870000"
        izz="0.0004566000"
        ixy="-0.0000000001"
        ixz="-0.0000000002"
        iyz="0.0004272000" />
    </inertial>
  </link>

  <joint name="elbow" type="revolute">
    <axis xyz="0 1 0" />
    <limit
      effort="${elbow_limit_effort}"
      lower="${elbow_limit_lower}"
      upper="${elbow_limit_upper}"
      velocity="${elbow_limit_vel}" />
    <origin
      rpy="0 ${initial_positions['elbow']} 0"
      xyz="0.04975 0 0.25" />
    <parent
      link="${robot_name}_upper_arm_link" />
    <child
      link="${robot_name}_upper_forearm_link" />
    <dynamics
      friction="0.1"
      damping="0.1" />
  </joint>

  <link name="${robot_name}_upper_forearm_link">
    <visual>
      <origin
        rpy="0 0 0"
        xyz="0 0 0" />
      <geometry>
        <mesh
          filename="${mesh_directory}/upper_forearm.stl"
          scale="0.001 0.001 0.001" />
      </geometry>
      <material name="interbotix_black" />
    </visual>
    <collision>
      <origin
        rpy="0 0 0"
        xyz="0 0 0" />
      <geometry>
        <mesh
          filename="${mesh_directory}/upper_forearm.stl"
          scale="0.001 0.001 0.001" />
      </geometry>
    </collision>
    <inertial>
      <origin
        rpy="0 0 0"
        xyz="0.1079630000 0.0001158760 0" />
      <mass value="0.234589" />
      <inertia
        ixx="0.0000397100"
        iyy="0.0008878000"
        izz="0.0008880000"
        ixy="0.0000023528"
        ixz="0"
        iyz="0" />
    </inertial>
  </link>

  <joint name="forearm_roll" type="revolute">
    <axis xyz="1 0 0" />
    <limit
      effort="${forearm_roll_limit_effort}"
      lower="${forearm_roll_limit_lower}"
      upper="${forearm_roll_limit_upper}"
      velocity="${forearm_roll_limit_vel}" />
    <origin rpy="${initial_positions['forearm_roll']} 0 0" xyz="0.175 0 0" />
    <parent
      link="${robot_name}_upper_forearm_link" />
    <child
      link="${robot_name}_lower_forearm_link" />
    <dynamics
      friction="0.1"
      damping="0.1" />
  </joint>

  <link name="${robot_name}_lower_forearm_link">
    <visual>
      <origin
        rpy="${pi} 0 0"
        xyz="0 0 0" />
      <geometry>
        <mesh
          filename="${mesh_directory}/lower_forearm.stl"
          scale="0.001 0.001 0.001" />
      </geometry>
      <material name="interbotix_black" />
    </visual>
    <collision>
      <origin
        rpy="${pi} 0 0"
        xyz="0 0 0" />
      <geometry>
        <mesh
          filename="${mesh_directory}/lower_forearm.stl"
          scale="0.001 0.001 0.001" />
      </geometry>
    </collision>
    <inertial>
      <origin
        rpy="${pi} 0 0"
        xyz="0.0374395000 0.0052225200 0" />
      <mass value="0.220991" />
      <inertia
        ixx="0.0000636900"
        iyy="0.0001677000"
        izz="0.0001834000"
        ixy="-0.0000229200"
        ixz="0"
        iyz="0" />
    </inertial>
  </link>

  <joint name="wrist_angle" type="revolute">
    <axis xyz="0 1 0" />
    <limit
      effort="${wrist_angle_limit_effort}"
      lower="${wrist_angle_limit_lower}"
      upper="${wrist_angle_limit_upper}"
      velocity="${wrist_angle_limit_vel}" />
    <origin
      rpy="0  ${initial_positions['wrist_angle']} 0"
      xyz="0.075 0 0" />
    <parent
      link="${robot_name}_lower_forearm_link" />
    <child
      link="${robot_name}_wrist_link" />
    <dynamics
      friction="0.1"
      damping="0.1" />
  </joint>

  <link name="${robot_name}_wrist_link">
    <visual>
      <origin
        rpy="0 0 ${pi/2}"
        xyz="0 0 0" />
      <geometry>
        <mesh
          filename="${mesh_directory}/wrist.stl"
          scale="0.001 0.001 0.001" />
      </geometry>
      <material name="interbotix_black" />
    </visual>
    <collision>
      <origin
        rpy="0 0 ${pi/2}"
        xyz="0 0 0" />
      <geometry>
        <mesh
          filename="${mesh_directory}/wrist.stl"
          scale="0.001 0.001 0.001" />
      </geometry>
    </collision>
    <inertial>
      <origin
        rpy="0 0 ${pi/2}"
        xyz="0.0423600000 -0.0000106630 0.0105770000" />
      <mass value="0.084957" />
      <inertia
        ixx="0.0000308200"
        iyy="0.0000282200"
        izz="0.0000315200"
        ixy="0.0000000191"
        ixz="0.0000000023"
        iyz="0.0000025481" />
    </inertial>
  </link>

    <joint name="wrist_rotate" type="revolute">
      <axis xyz="1 0 0" />
      <limit
        effort="${wrist_rotate_limit_effort}"
        lower="${wrist_rotate_limit_lower}"
        upper="${wrist_rotate_limit_upper}"
        velocity="${wrist_rotate_limit_vel}" />
      <origin
        rpy="${initial_positions['wrist_rotate']} 0 0"
        xyz="0.065 0 0" />
      <parent
        link="${robot_name}_wrist_link" />
      <child
        link="${robot_name}_gripper_link" />
      <dynamics
        friction="0.1"
        damping="0.1" />
    </joint>

    <link name="${robot_name}_gripper_link">
      <visual>
        <origin
          rpy="0 0 ${pi/2}"
          xyz="-0.02 0 0" />
        <geometry>
          <mesh
            filename="${mesh_directory}/gripper.stl"
            scale="0.001 0.001 0.001" />
        </geometry>
        <material name="interbotix_black" />
      </visual>
      <collision>
        <origin
          rpy="0 0 ${pi/2}"
          xyz="-0.02 0 0" />
        <geometry>
          <mesh
            filename="${mesh_directory}/gripper.stl"
            scale="0.001 0.001 0.001" />
        </geometry>
      </collision>
      <inertial>
        <origin
          rpy="0 0 ${pi/2}"
          xyz="0.0216310000 0.0000002516 0.0114100000" />
        <mass value="0.072885" />
        <inertia
          ixx="0.0000253700"
          iyy="0.0000183600"
          izz="0.0000167400"
          ixy="0"
          ixz="0"
          iyz="0.0000004340" />
      </inertial>
    </link>

    <joint name="ee_arm" type="fixed">
      <axis xyz="1 0 0" />
      <origin
        rpy="0 0 0"
        xyz="0.043 0 0" />
      <parent
        link="${robot_name}_gripper_link" />
      <child
        link="${robot_name}_ee_arm_link" />
    </joint>

    <link name="${robot_name}_ee_arm_link">
      <inertial>
        <mass value="0.001" />
        <inertia
          ixx="0.001"
          iyy="0.001"
          izz="0.001"
          ixy="0"
          ixz="0"
          iyz="0" />
      </inertial>
    </link>

    <joint name="gripper" type="continuous">
      <axis xyz="1 0 0" />
      <limit
        effort="1"
        velocity="${gripper_limit_vel}" />
      <origin
        rpy="0 0 0"
        xyz="0.0055 0 0" />
      <parent
        link="${robot_name}_ee_arm_link" />
      <child
        link="${robot_name}_gripper_prop_link" />
      <dynamics
        friction="0.1"
        damping="0.1" />
    </joint>

    <link name="${robot_name}_gripper_prop_link">
      <visual>
        <origin
          rpy="0 0 ${pi/2}"
          xyz="-0.0685 0 0" />
        <geometry>
          <mesh
            filename="${mesh_directory}/gripper_prop.stl"
            scale="0.001 0.001 0.001" />
        </geometry>
        <material name="interbotix_black" />
      </visual>
      <collision>
        <origin
          rpy="0 0 ${pi/2}"
          xyz="-0.0685 0 0" />
        <geometry>
          <mesh
            filename="${mesh_directory}/gripper_prop.stl"
            scale="0.001 0.001 0.001" />
        </geometry>
      </collision>
      <inertial>
        <origin
          rpy="0 0 ${pi/2}"
          xyz="0.0008460000 -0.0000016817 0.0000420000" />
        <mass value="0.00434" />
        <inertia
          ixx="0.0000005923"
          iyy="0.0000011156"
          izz="0.0000005743"
          ixy="0"
          ixz="0.0000003195"
          iyz="-0.0000000004" />
      </inertial>
    </link>



      <joint name="gripper_bar" type="fixed">
        <axis xyz="1 0 0" />
        <origin
          rpy="0 0 0"
          xyz="0 0 0" />
        <parent
          link="${robot_name}_ee_arm_link" />
        <child
          link="${robot_name}_gripper_bar_link" />
      </joint>

      <link name="${robot_name}_gripper_bar_link">
        <visual>
          <origin
            rpy="0 0 ${pi/2}"
            xyz="-0.063 0 0" />
          <geometry>
            <mesh
              filename="${mesh_directory}/gripper_bar.stl"
              scale="0.001 0.001 0.001" />
          </geometry>
          <material name="interbotix_black" />

        </visual>
        <collision>
          <origin
            rpy="0 0 ${pi/2}"
            xyz="-0.063 0 0" />
          <geometry>
            <mesh
              filename="${mesh_directory}/gripper_bar.stl"
              scale="0.001 0.001 0.001" />
          </geometry>
        </collision>
        <inertial>
          <origin
            rpy="0 0 ${pi/2}"
            xyz="0.0096870000 0.0000008177 0.0049620000" />
          <mass value="0.034199" />
          <inertia
            ixx="0.0000074125"
            iyy="0.0000284300"
            izz="0.0000286000"
            ixy="-0.0000000008"
            ixz="-0.0000000006"
            iyz="-0.0000013889" />
        </inertial>
      </link>

      <joint name="ee_bar" type="fixed">
        <axis xyz="1 0 0" />
        <origin rpy="0 0 0" xyz="0.023 0 0" />
        <parent
          link="${robot_name}_gripper_bar_link" />
        <child
          link="${robot_name}_fingers_link" />
      </joint>

      <link name="${robot_name}_fingers_link">
        <inertial>
          <mass value="0.001" />
          <inertia
            ixx="0.001"
            iyy="0.001"
            izz="0.001"
            ixy="0"
            ixz="0"
            iyz="0" />
        </inertial>
      </link>
        <joint name="left_finger" type="prismatic">
          <axis xyz="0 1 0" />
          <limit
            effort="${finger_limit_effort}"
            lower="${finger_limit_lower}"
            upper="${finger_limit_upper}"
            velocity="${finger_limit_vel}" />
          <origin
            rpy="0 0 0"
            xyz="0 ${initial_positions['left_finger']} 0" />
          <parent
            link="${robot_name}_fingers_link" />
          <child
            link="${robot_name}_left_finger_link" />
          <dynamics
            friction="0.1"
            damping="0.1" />
        </joint>

        <link name="${robot_name}_left_finger_link">
          <visual>
            <origin
              rpy="${pi} ${pi} 0"
              xyz="0 0.005 0" />
            <geometry>
              <mesh
                filename="${mesh_directory}/gripper_finger.stl"
                scale="0.001 0.001 0.001" />
            </geometry>
            <material name="interbotix_black" />

          </visual>
          <collision>
            <origin
              rpy="${pi} ${pi} 0" xyz="0 0.005 0" />
            <geometry>
              <mesh
                filename="${mesh_directory}/gripper_finger.stl"
                scale="0.001 0.001 0.001" />
            </geometry>
          </collision>
          <inertial>
            <origin
              rpy="${pi} ${pi} ${pi/2}"
              xyz="0.0138160000 0 0" />
            <mass value="0.016246" />
            <inertia
              ixx="0.0000047310"
              iyy="0.0000015506"
              izz="0.0000037467"
              ixy="-0.0000004560"
              ixz="0"
              iyz="0" />
          </inertial>
        </link>

        <joint name="right_finger" type="prismatic">
          <axis xyz="0 1 0" />
          <limit
            effort="${finger_limit_effort}"
            lower="${-finger_limit_upper}"
            upper="${-finger_limit_lower}"
            velocity="${finger_limit_vel}" />
          <origin
            rpy="0 0 0"
            xyz="0  ${initial_positions['right_finger']} 0" />
          <parent
            link="${robot_name}_fingers_link" />
          <child
            link="${robot_name}_right_finger_link" />
          <dynamics
            friction="0.1"
            damping="0.1" />
          <!-- <xacro:unless value="${hardware_type in ('gz_classic', 'gz_ignition')}">
            <mimic
              joint="left_finger"
              multiplier="-1"
              offset="0" />
          </xacro:unless> -->
        </joint>

        <link name="${robot_name}_right_finger_link">
          <visual>
            <origin
              rpy="0 ${pi} 0"
              xyz="0 -0.005 0" />
            <geometry>
              <mesh
                filename="${mesh_directory}/gripper_finger.stl"
                scale="0.001 0.001 0.001" />
            </geometry>
            <material name="interbotix_black" />

          </visual>
          <collision>
            <origin
              rpy="0 ${pi} 0"
              xyz="0 -0.005 0" />
            <geometry>
              <mesh
                filename="${mesh_directory}/gripper_finger.stl"
                scale="0.001 0.001 0.001" />
            </geometry>
          </collision>
          <inertial>
            <origin
              rpy="0 ${pi} ${pi/2}"
              xyz="0.0138160000 0  0" />
            <mass value="0.016246" />
            <inertia
              ixx="0.0000047310"
              iyy="0.0000015506"
              izz="0.0000037467"
              ixy="0.0000004560"
              ixz="0"
              iyz="0" />
          </inertial>
        </link>

        <joint name="ee_gripper" type="fixed">
          <axis xyz="1 0 0" />
          <origin
            rpy="0 0 0"
            xyz="0.027575 0 0" />
          <parent
            link="${robot_name}_fingers_link" />
          <child
            link="${robot_name}_ee_gripper_link" />
        </joint>

        <link name="${robot_name}_ee_gripper_link">
          <inertial>
            <mass value="0.001" />
            <inertia
              ixx="0.001"
              iyy="0.001"
              izz="0.001"
              ixy="0"
              ixz="0"
              iyz="0" />
          </inertial>
        </link>
        <gazebo reference="${robot_name}_ar_tag_link">
          <visual>
            <material>
              <xacro:include
                filename="$(find ros2_transformers)/robots/locobot_wx250s/description/urdf/colors.urdf.xacro" />
              <xacro:color color="black" />
            </material>
          </visual>
        </gazebo>
        <gazebo reference="{robot_name}_arm_base_link">
          <visual>
            <material>
              <xacro:include
                filename="$(find ros2_transformers)/robots/locobot_wx250s/description/urdf/colors.urdf.xacro" />
              <xacro:color color="black" />
            </material>
          </visual>
        </gazebo>
        <gazebo reference="${robot_name}_shoulder_link">
          <visual>
            <material>
              <xacro:include
                filename="$(find ros2_transformers)/robots/locobot_wx250s/description/urdf/colors.urdf.xacro" />
              <xacro:color color="black" />
            </material>

          </visual>
        </gazebo>
        <gazebo reference="${robot_name}_upper_arm_link">
          <visual>
            <material>
              <xacro:include
                filename="$(find ros2_transformers)/robots/locobot_wx250s/description/urdf/colors.urdf.xacro" />
              <xacro:color color="black" />
            </material>

          </visual>
        </gazebo>
        <gazebo reference="${robot_name}_upper_forearm_link">
          <visual>
            <material>
              <xacro:include
                filename="$(find ros2_transformers)/robots/locobot_wx250s/description/urdf/colors.urdf.xacro" />
              <xacro:color color="black" />
            </material>

          </visual>
        </gazebo>
        <gazebo reference="${robot_name}_lower_forearm_link">
          <visual>
            <material>
              <xacro:include
                filename="$(find ros2_transformers)/robots/locobot_wx250s/description/urdf/colors.urdf.xacro" />
              <xacro:color color="black" />
            </material>

          </visual>
        </gazebo>
        <gazebo reference="${robot_name}_wrist_link">
          <visual>
            <material>
              <xacro:include
                filename="$(find ros2_transformers)/robots/locobot_wx250s/description/urdf/colors.urdf.xacro" />
              <xacro:color color="black" />
            </material>

          </visual>
        </gazebo>
        <gazebo reference="${robot_name}_gripper_link">
          <visual>
            <material>
              <xacro:include
                filename="$(find ros2_transformers)/robots/locobot_wx250s/description/urdf/colors.urdf.xacro" />
              <xacro:color color="black" />
            </material>

          </visual>
        </gazebo>
        <gazebo reference="${robot_name}_gripper_prop_link">
          <visual>
            <material>
              <xacro:include
                filename="$(find ros2_transformers)/robots/locobot_wx250s/description/urdf/colors.urdf.xacro" />
              <xacro:color color="black" />
            </material>

          </visual>
        </gazebo>
        <gazebo reference="${robot_name}_ee_arm_link">
          <visual>
            <material>
              <xacro:include
                filename="$(find ros2_transformers)/robots/locobot_wx250s/description/urdf/colors.urdf.xacro" />
              <xacro:color color="black" />
            </material>

          </visual>
        </gazebo>
        <gazebo reference="${robot_name}_fingers_link">
          <visual>
            <material>
              <xacro:include
                filename="$(find ros2_transformers)/robots/locobot_wx250s/description/urdf/colors.urdf.xacro" />
              <xacro:color color="black" />
            </material>

          </visual>
        </gazebo>
        <gazebo reference="${robot_name}_ee_gripper_link">
          <visual>
            <material>
              <xacro:include
                filename="$(find ros2_transformers)/robots/locobot_wx250s/description/urdf/colors.urdf.xacro" />
              <xacro:color color="black" />
            </material>

          </visual>
        </gazebo>
        
        
        <gazebo reference="${robot_name}_gripper_link">
          <visual>
            <material>
              <xacro:include
                filename="$(find ros2_transformers)/robots/locobot_wx250s/description/urdf/colors.urdf.xacro" />
              <xacro:color color="black" />
            </material>

          </visual>
        </gazebo>
        <gazebo reference="${robot_name}_gripper_bar_link">
          <visual>
            <material>
              <xacro:include
                filename="$(find ros2_transformers)/robots/locobot_wx250s/description/urdf/colors.urdf.xacro" />
              <xacro:color color="black" />
            </material>

          </visual>
        </gazebo>
        <gazebo reference="${robot_name}_left_finger_link">
          <visual>
            <material>
              <xacro:include
                filename="$(find ros2_transformers)/robots/locobot_wx250s/description/urdf/colors.urdf.xacro" />
              <xacro:color color="black" />
            </material>

          </visual>
        </gazebo>
        <gazebo reference="${robot_name}_right_finger_link">
          <visual>
            <material>
              <xacro:include
                filename="$(find ros2_transformers)/robots/locobot_wx250s/description/urdf/colors.urdf.xacro" />
              <xacro:color color="black" />
            </material>

          </visual>
        </gazebo>
      

</robot>